Workbook

Sheet AM
A1: TRANSPORTATION TYPE FOR SHIPPING VOLUME (AMTOPP)
A4: Product | B4: Transportation | C4: 20/01 | E4: 20/02 | G4: 20/03 | I4: 20/04 | K4: 20/05 | M4: 20/06 | O4: 20/07 | Q4: 20/08 | S4: 20/09 | U4: 20/10 | W4: 20/11 | Y4: 20/12 | AA4: 21/01 | AC4: 21/02 | AE4: 21/03 | AG4: 21/04 | AI4: 21/05 | AK4: 21/06 | AM4: 21/07 | AO4: 21/08 | AQ4: 21/09 | AS4: 21/10 | AU4: 21/11 | AW4: 21/12 | AY4: 22/01 | BA4: 22/02 | BC4: 22/03 | BE4: 22/04 | BG4: 22/05 | BI4: 22/06 | BK4: 22/07 | BM4: 22/08 | BO4: 22/09 | BQ4: 22/10 | BS4: 22/11 | BU4: 22/12 | BW4: 23/01 | BY4: 23/02 | CA4: 23/03 | CC4: 23/04 | CE4: 23/05 | CG4: 23/06 | CI4: 23/07 | CK4: 23/08 | CM4: 23/09 | CO4: 23/10 | CQ4: 23/11 | CS4: 23/12 | CU4: 24/01 | CW4: 24/02 | CY4: 24/03 | DA4: 24/04 | DC4: 24/05 | DE4: 24/06 | DG4: 24/07 | DI4: 24/08 | DK4: 24/09 | DM4: 24/10 | DO4: 24/11 | DQ4: 24/12 | DS4: 25/01 | DU4: 25/02 | DW4: 25/03 | DY4: 25/04 | EA4: 25/05 | EC4: 25/06 | EE4: 25/07 | EG4: 25/08 | EI4: 25/09 | EK4: 25/10 | EM4: 25/11 | EO4: 25/12 | EQ4: 26/01 | ES4: 26/02 | EU4: 2026 YTD-Avg
B5: Type | C5: Weight | D5: % | E5: Weight | F5: % | G5: Weight | H5: % | I5: Weight | J5: % | K5: Weight | L5: % | M5: Weight | N5: % | O5: Weight | P5: % | Q5: Weight | R5: % | S5: Weight | T5: % | U5: Weight | V5: % | W5: Weight | X5: % | Y5: Weight | Z5: % | AA5: Weight | AB5: % | AC5: Weight | AD5: % | AE5: Weight | AF5: % | AG5: Weight | AH5: % | AI5: Weight | AJ5: % | AK5: Weight | AL5: % | AM5: Weight | AN5: % | AO5: Weight | AP5: % | AQ5: Weight | AR5: % | AS5: Weight | AT5: % | AU5: Weight | AV5: % | AW5: Weight | AX5: % | AY5: Weight | AZ5: % | BA5: Weight | BB5: % | BC5: Weight | BD5: % | BE5: Weight | BF5: % | BG5: Weight | BH5: % | BI5: Weight | BJ5: % | BK5: Weight | BL5: % | BM5: Weight | BN5: % | BO5: Weight | BP5: % | BQ5: Weight | BR5: % | BS5: Weight | BT5: % | BU5: Weight | BV5: % | BW5: Weight | BX5: % | BY5: Weight | BZ5: % | CA5: Weight | CB5: % | CC5: Weight | CD5: % | CE5: Weight | CF5: % | CG5: Weight | CH5: % | CI5: Weight | CJ5: % | CK5: Weight | CL5: % | CM5: Weight | CN5: % | CO5: Weight | CP5: % | CQ5: Weight | CR5: % | CS5: Weight | CT5: % | CU5: Weight | CV5: % | CW5: Weight | CX5: % | CY5: Weight | CZ5: % | DA5: Weight | DB5: % | DC5: Weight | DD5: % | DE5: Weight | DF5: % | DG5: Weight | DH5: % | DI5: Weight | DJ5: % | DK5: Weight | DL5: % | DM5: Weight | DN5: % | DO5: Weight | DP5: % | DQ5: Weight | DR5: % | DS5: Weight | DT5: % | DU5: Weight | DV5: % | DW5: Weight | DX5: % | DY5: Weight | DZ5: % | EA5: Weight | EB5: % | EC5: Weight | ED5: % | EE5: Weight | EF5: % | EG5: Weight | EH5: % | EI5: Weight | EJ5: % | EK5: Weight | EL5: % | EM5: Weight | EN5: % | EO5: Weight | EP5: % | EQ5: Weight | ER5: % | ES5: Weight | ET5: % | EU5: Weight | EV5: % | EX5: Type | EZ5: Space
B6: Intermodal | C6: 0 | D6: 0 | E6: 0 | F6: 0 | G6: 0 | H6: 0 | I6: 0 | J6: 0 | K6: 0 | L6: 0 | M6: 0 | N6: 0 | O6: 0 | P6: 0 | Q6: 0 | R6: 0 | S6: 0 | T6: 0 | U6: 0 | V6: 0 | W6: 0 | X6: 0 | Y6: 74629 | Z6: 0.0051750584 | AA6: 37449 | AB6: 0.0021498628 | AC6: 0 | AD6: 0 | AE6: 0 | AF6: 0 | AG6: 0 | AH6: 0 | AI6: 0 | AJ6: 0 | AK6: 0 | AL6: 0 | AM6: 0 | AN6: 0 | AO6: 0 | AP6: 0 | AQ6: 0 | AR6: 0 | AS6: 0 | AT6: 0 | AU6: 0 | AV6: 0 | AW6: 0 | AX6: 0 | AY6: 0 | AZ6: 0 | BA6: 0 | BB6: 0 | BC6: 0 | BD6: 0 | BE6: 0 | BF6: 0 | BG6: 0 | BH6: 0 | BI6: 0 | BJ6: 0 | BK6: 0 | BL6: 0 | BM6: 0 | BN6: 0 | BO6: 0 | BP6: 0 | BQ6: 0 | BR6: 0 | BS6: 0 | BT6: 0 | BU6: 0 | BV6: 0 | BW6: 0 | BX6: 0 | BY6: 0 | BZ6: 0 | CA6: 0 | CB6: 0 | CC6: 0 | CD6: 0 | CE6: 0 | CF6: 0 | CG6: 0 | CH6: 0 | CI6: 0 | CJ6: 0 | CK6: 0 | CL6: 0 | CM6: 0 | CN6: 0 | CO6: 0 | CP6: 0 | CQ6: 0 | CR6: 0 | CS6: 0 | CT6: 0 | CU6: 0 | CV6: 0 | CW6: 0 | CX6: 0 | CY6: 0 | CZ6: 0 | DA6: 0 | DB6: 0 | DC6: 0 | DD6: 0 | DE6: 0 | DF6: 0 | DG6: 0 | DH6: 0 | DI6: 0 | DJ6: 0 | DK6: 0 | DL6: 0 | DM6: 0 | DN6: 0 | DO6: 0 | DP6: 0 | DQ6: 0 | DR6: 0 | DS6: 0 | DT6: 0 | DU6: 0 | DV6: 0 | DW6: 0 | DX6: 0 | DY6: 0 | DZ6: 0 | EA6: 0 | EB6: 0 | EC6: 0 | ED6: 0 | EE6: 0 | EF6: 0 | EG6: 0 | EH6: 0 | EI6: 0 | EJ6: 0 | EK6: 0 | EL6: 0 | EM6: 0 | EN6: 0 | EO6: 0 | EP6: 0 | EQ6: 0 | ER6: 0 | ES6: =+$EY6 -> 0 | ET6: =ES6/ES13 -> 0 | EU6: =IF( SUM($EQ6:ES6)<0, "n/a", SUM($EQ6:ES6)/EU$74) -> 0 | EV6: =EU6/EU13 -> 0 | EX6: AMBI | EY6: =IF(ISERROR(VLOOKUP(EX6,IQSH01E!$A$1:$M$400,2,0)),0,VLOOKUP(EX6,IQSH01E!$A$1:$M$400,2,0)) -> 0 | EZ6: no
B7: FTL | C7: 17926960 | D7: 0.94436455 | E7: 14757649 | F7: 0.92598855 | G7: 18016503 | H7: 0.93788087 | I7: 20241203 | J7: 0.9719894 | K7: 17563611 | L7: 0.96731644 | M7: 16544199 | N7: 0.94564455 | O7: 19119684 | P7: 0.92215143 | Q7: 17440860 | R7: 0.9234138 | S7: 16221820 | T7: 0.88934773 | U7: 14767751 | V7: 0.89908923 | W7: 12597716 | X7: 0.9106403 | Y7: 13079418 | Z7: 0.90697654 | AA7: 16339316 | AB7: 0.93800336 | AC7: 12209783 | AD7: 0.91449082 | AE7: 10897719 | AF7: 0.90107998 | AG7: 15419469 | AH7: 0.94789939 | AI7: 14387713 | AJ7: 0.92196141 | AK7: 11868724 | AL7: 0.89870219 | AM7: 14270149 | AN7: 0.94123838 | AO7: 13769270 | AP7: 0.96331196 | AQ7: 14072832 | AR7: 0.94554686 | AS7: 14038582 | AT7: 0.96043977 | AU7: 14699148 | AV7: 0.96509261 | AW7: 14322845 | AX7: 0.95562867 | AY7: 14395924 | AZ7: 0.95991609 | BA7: 13011428 | BB7: 0.94883497 | BC7: 16081880 | BD7: 0.94503862 | BE7: 15064453 | BF7: 0.95105683 | BG7: 14718908 | BH7: 0.93858394 | BI7: 15878802 | BJ7: 0.93071118 | BK7: 13620471 | BL7: 0.92851367 | BM7: 13541155 | BN7: 0.92552832 | BO7: 13392133 | BP7: 0.94825397 | BQ7: 12948095 | BR7: 0.89412537 | BS7: 12326265 | BT7: 0.91283468 | BU7: 9917416 | BV7: 0.905166 | BW7: 13127731 | BX7: 0.92829391 | BY7: 10939993 | BZ7: 0.92906917 | CA7: 14198672 | CB7: 0.93040259 | CC7: 10525066 | CD7: 0.94890402 | CE7: 12518070 | CF7: 0.95415544 | CG7: 11553940 | CH7: 0.91770114 | CI7: 11196745 | CJ7: 0.95451912 | CK7: 12662929 | CL7: 0.93925445 | CM7: 11987003 | CN7: 0.95242334 | CO7: 11670626 | CP7: 0.94901887 | CQ7: 12202598 | CR7: 0.95833617 | CS7: 10634147 | CT7: 0.94814603 | CU7: 14109935 | CV7: 0.94703506 | CW7: 11965010 | CX7: 0.9573238 | CY7: 13077374 | CZ7: 0.948332 | DA7: 14596481 | DB7: 0.94974717 | DC7: 14318378 | DD7: 0.93990664 | DE7: 13655036 | DF7: 0.96243592 | DG7: 13912251 | DH7: 0.95450414 | DI7: 14358254 | DJ7: 0.97088033 | DK7: 13299292 | DL7: 0.92273949 | DM7: 12533567 | DN7: 0.92305877 | DO7: 10506830 | DP7: 0.95381896 | DQ7: 12522037 | DR7: 0.95228099 | DS7: 12167480 | DT7: 0.95139447 | DU7: 11294806 | DV7: 0.94330762 | DW7: 11957761 | DX7: 0.94320035 | DY7: 11187257 | DZ7: 0.95760157 | EA7: 11395304 | EB7: 0.93657605 | EC7: 9631958 | ED7: 0.95044257 | EE7: 9911399 | EF7: 0.92687996 | EG7: 10989846 | EH7: 0.94528414 | EI7: 11856096 | EJ7: 0.97763247 | EK7: 10866329 | EL7: 0.96234294 | EM7: 8568924 | EN7: 0.97460566 | EO7: 9066698 | EP7: 0.94328364 | EQ7: 9797301 | ER7: 0.9333691 | ES7: =+$EY7 -> 9575398 | ET7: =ES7/ES13 -> 0.94442756 | EU7: =IF( SUM($EQ7:ES7)<0, "n/a", SUM($EQ7:ES7)/EU$74) -> 9686350 | EV7: =EU7/EU13 -> 0.93880244 | EX7: All Others | EY7: =+EY16-EY15-EY14-EY6-EY9-EY10-EY11-EY12-EY8 -> 9575398
B8: Railcar | C8: 0 | D8: 0 | E8: 0 | F8: 0 | G8: 0 | H8: 0 | I8: 0 | J8: 0 | K8: 0 | L8: 0 | M8: 0 | N8: 0 | O8: 0 | P8: 0 | Q8: 0 | R8: 0 | S8: 0 | T8: 0 | U8: 0 | V8: 0 | W8: 0 | X8: 0 | Y8: 0 | Z8: 0 | AA8: 0 | AB8: 0 | AC8: 0 | AD8: 0 | AE8: 0 | AF8: 0 | AG8: 0 | AH8: 0 | AI8: 0 | AJ8: 0 | AK8: 0 | AL8: 0 | AM8: 0 | AN8: 0 | AO8: 0 | AP8: 0 | AQ8: 0 | AR8: 0 | AS8: 0 | AT8: 0 | AU8: 0 | AV8: 0 | AW8: 0 | AX8: 0 | AY8: 0 | AZ8: 0 | BA8: 0 | BB8: 0 | BC8: 0 | BD8: 0 | BE8: 0 | BF8: 0 | BG8: 0 | BH8: 0 | BI8: 0 | BJ8: 0 | BK8: 0 | BL8: 0 | BM8: 0 | BN8: 0 | BO8: 0 | BP8: 0 | BQ8: 0 | BR8: 0 | BS8: 0 | BT8: 0 | BU8: 0 | BV8: 0 | BW8: 0 | BX8: 0 | BY8: 0 | BZ8: 0 | CA8: 0 | CB8: 0 | CC8: 0 | CD8: 0 | CE8: 0 | CF8: 0 | CG8: 0 | CH8: 0 | CI8: 0 | CJ8: 0 | CK8: 0 | CL8: 0 | CM8: 0 | CN8: 0 | CO8: 0 | CP8: 0 | CQ8: 0 | CR8: 0 | CS8: 0 | CT8: 0 | CU8: 0 | CV8: 0 | CW8: 0 | CX8: 0 | CY8: 0 | CZ8: 0 | DA8: 0 | DB8: 0 | DC8: 0 | DD8: 0 | DE8: 0 | DF8: 0 | DG8: 0 | DH8: 0 | DI8: 0 | DJ8: 0 | DK8: 0 | DL8: 0 | DM8: 0 | DN8: 0 | DO8: 0 | DP8: 0 | DQ8: 0 | DR8: 0 | DS8: 0 | DT8: 0 | DU8: 0 | DV8: 0 | DW8: 0 | DX8: 0 | DY8: 0 | DZ8: 0 | EA8: 0 | EB8: 0 | EC8: 0 | ED8: 0 | EE8: 0 | EF8: 0 | EG8: 0 | EH8: 0 | EI8: 0 | EJ8: 0 | EK8: 0 | EL8: 0 | EM8: 0 | EN8: 0 | EO8: 0 | EP8: 0 | EQ8: 0 | ER8: 0 | ES8: =+$EY8 -> 0 | ET8: =ES8/ES13 -> 0 | EU8: =IF( SUM($EQ8:ES8)<0, "n/a", SUM($EQ8:ES8)/EU$74) -> 0 | EV8: =EU8/EU13 -> 0 | EX8: AMB RC | EY8: =IF(ISERROR(VLOOKUP(EX8,IQSH01E!$A$1:$M$400,2,0)),0,VLOOKUP(EX8,IQSH01E!$A$1:$M$400,2,0)) -> 0 | EZ8: 2 spaces
B9: LTL | C9: 308616 | D9: 0.016257414 | E9: 208608 | F9: 0.01308939 | G9: 295848 | H9: 0.01540089 | I9: 389602 | J9: 0.01870882 | K9: 251722 | L9: 0.013863597 | M9: 314430 | N9: 0.017972403 | O9: 368155 | P9: 0.01775629 | Q9: 331899 | R9: 0.017572535 | S9: 488051 | T9: 0.026756988 | U9: 610068 | V9: 0.037142119 | W9: 477027 | X9: 0.034482442 | Y9: 512781 | Z9: 0.035558183 | AA9: 327005 | AB9: 0.018772621 | AC9: 348770 | AD9: 0.026122247 | AE9: 477903 | AF9: 0.039515502 | AG9: 379079 | AH9: 0.023303575 | AI9: 372609 | AJ9: 0.023876701 | AK9: 450811 | AL9: 0.034135501 | AM9: 545091 | AN9: 0.035953414 | AO9: 329851 | AP9: 0.023076707 | AQ9: 392295 | AR9: 0.026358114 | AS9: 382415 | AT9: 0.026162655 | AU9: 257945 | AV9: 0.016935731 | AW9: 396921 | AX9: 0.026482803 | AY9: 245984 | AZ9: 0.016402143 | BA9: 287236 | BB9: 0.020946168 | BC9: 392906 | BD9: 0.023088802 | BE9: 338374 | BF9: 0.021362402 | BG9: 303251 | BH9: 0.019337475 | BI9: 354265 | BJ9: 0.02076469 | BK9: 269449 | BL9: 0.01836846 | BM9: 357509 | BN9: 0.024435486 | BO9: 259589 | BP9: 0.018380664 | BQ9: 337199 | BR9: 0.023285138 | BS9: 248594 | BT9: 0.018409893 | BU9: 262899 | BV9: 0.023994883 | BW9: 240751 | BX9: 0.017024091 | BY9: 169317 | BZ9: 0.014379096 | CA9: 322774 | CB9: 0.021150553 | CC9: 273458 | CD9: 0.02465404 | CE9: 319066 | CF9: 0.024319928 | CG9: 348652 | CH9: 0.027692574 | CI9: 259715 | CJ9: 0.022140625 | CK9: 282685 | CL9: 0.020967751 | CM9: 217317 | CN9: 0.01726685 | CO9: 203753 | CP9: 0.016568558 | CQ9: 214739 | CR9: 0.016864618 | CS9: 155566 | CT9: 0.013870345 | CU9: 161940 | CV9: 0.01086914 | CW9: 211993 | CX9: 0.016961619 | CY9: 206988 | CZ9: 0.01501015 | DA9: 274571 | DB9: 0.017865473 | DC9: 254356 | DD9: 0.016696786 | DE9: 236661 | DF9: 0.01668037 | DG9: 155041 | DH9: 0.010637191 | DI9: 166806 | DJ9: 0.011279134 | DK9: 145714 | DL9: 0.010110017 | DM9: 264581 | DN9: 0.019485579 | DO9: 266475 | DP9: 0.024190827 | DQ9: 171161 | DR9: 0.013016522 | DS9: 193870 | DT9: 0.015159001 | DU9: 227913 | DV9: 0.019034596 | DW9: 265422 | DX9: 0.020935869 | DY9: 216415 | DZ9: 0.01852459 | EA9: 216738 | EB9: 0.017813621 | EC9: 159328 | ED9: 0.015721841 | EE9: 130887 | EF9: 0.012240102 | EG9: 215728 | EH9: 0.018555697 | EI9: 151079 | EJ9: 0.012457704 | EK9: 191453 | EL9: 0.016955445 | EM9: 113111 | EN9: 0.012864932 | EO9: 158918 | EP9: 0.016533555 | EQ9: 160597 | ER9: 0.015299752 | ES9: =+$EY9 -> 206233 | ET9: =ES9/ES13 -> 0.020340891 | EU9: =IF( SUM($EQ9:ES9)<0, "n/a", SUM($EQ9:ES9)/EU$74) -> 183415.01 | EV9: =EU9/EU13 -> 0.017776609 | EX9: AMB L | EY9: =IF(ISERROR(VLOOKUP(EX9,IQSH01E!$A$1:$M$400,2,0)),0,VLOOKUP(EX9,IQSH01E!$A$1:$M$400,2,0)) -> 206233 | EZ9: 1 space
B10: Export | C10: 734203 | D10: 0.038676679 | E10: 960281 | F10: 0.060254124 | G10: 890325 | H10: 0.04634744 | I10: 189422 | J10: 0.0090961084 | K10: 289729 | L10: 0.015956834 | M10: 628390 | N10: 0.035917942 | O10: 1232639 | P10: 0.059450764 | Q10: 1110142 | R10: 0.058776944 | S10: 1523341 | T10: 0.083515898 | U10: 1035547 | V10: 0.063046103 | W10: 751933 | X10: 0.054354337 | Y10: 747907 | Z10: 0.051862713 | AA10: 709138 | AB10: 0.040710017 | AC10: 786952 | AD10: 0.058941291 | AE10: 708372 | AF10: 0.058571875 | AG10: 461298 | AH10: 0.028357922 | AI10: 841299 | AJ10: 0.05391025 | AK10: 882264 | AL10: 0.066805209 | AM10: 340715 | AN10: 0.022473068 | AO10: 189050 | AP10: 0.013226128 | AQ10: 418146 | AR10: 0.02809503 | AS10: 191320 | AT10: 0.013089024 | AU10: 270601 | AV10: 0.017766678 | AW10: 263567 | AX10: 0.017585346 | AY10: 349008 | AZ10: 0.023271754 | BA10: 412060 | BB10: 0.030048734 | BC10: 533661 | BD10: 0.031360155 | BE10: 433203 | BF10: 0.027349196 | BG10: 620090 | BH10: 0.039541419 | BI10: 809420 | BJ10: 0.047442889 | BK10: 774601 | BL10: 0.052804901 | BM10: 726886 | BN10: 0.049682142 | BO10: 457657 | BP10: 0.032405224 | BQ10: 1187749 | BR10: 0.082019518 | BS10: 913902 | BT10: 0.067679986 | BU10: 770476 | BV10: 0.070321612 | BW10: 769665 | BX10: 0.054424891 | BY10: 658854 | BZ10: 0.05595259 | CA10: 731322 | CB10: 0.047921656 | CC10: 266825 | CD10: 0.024056031 | CE10: 268493 | CF10: 0.02046514 | CG10: 683839 | CH10: 0.054315656 | CI10: 269412 | CJ10: 0.022967291 | CK10: 532727 | CL10: 0.039514255 | CM10: 371605 | CN10: 0.029525752 | CO10: 421100 | CP10: 0.034242537 | CQ10: 306002 | CR10: 0.024031996 | CS10: 419666 | CT10: 0.037417637 | CU10: 612193 | CV10: 0.041089362 | CW10: 307220 | CX10: 0.024580758 | CY10: 494734 | CZ10: 0.035876628 | DA10: 491195 | DB10: 0.031960516 | DC10: 651799 | DD10: 0.042786286 | DE10: 291372 | DF10: 0.020536517 | DG10: 496528 | DH10: 0.034066236 | DI10: 260111 | DJ10: 0.017588256 | DK10: 962039 | DL10: 0.066748769 | DM10: 765616 | DN10: 0.05638527 | DO10: 228878 | DP10: 0.02077774 | DQ10: 453068 | DR10: 0.034455101 | DS10: 424836 | DT10: 0.033218598 | DU10: 449007 | DV10: 0.03749969 | DW10: 442051 | DX10: 0.034867954 | DY10: 270330 | DZ10: 0.02313958 | EA10: 533847 | EB10: 0.043876698 | EC10: 341323 | ED10: 0.03368037 | EE10: 644507 | EF10: 0.060272079 | EG10: 412282 | EH10: 0.035462156 | EI10: 114601 | EJ10: 0.0094497935 | EK10: 225346 | EL10: 0.019957074 | EM10: 69439 | EN10: 0.0078977994 | EO10: 377281 | EP10: 0.039251665 | EQ10: 529372 | ER10: 0.050432202 | ES10: =+$EY10 -> 341095 | ET10: =ES10/ES13 -> 0.033642415 | EU10: =IF( SUM($EQ10:ES10)<0, "n/a", SUM($EQ10:ES10)/EU$74) -> 435233.53 | EV10: =EU10/EU13 -> 0.042182896 | EX10: AMBE | EY10: =IF(ISERROR(VLOOKUP(EX10,IQSH01E!$A$1:$M$400,2,0)),0,VLOOKUP(EX10,IQSH01E!$A$1:$M$400,2,0)) -> 341095 | EZ10: no
A11: BOPP | B11: Sample | C11: 13314 | D11: 0.00070136094 | E11: 10645 | F11: 0.00066793485 | G11: 7123 | H11: 0.00037080034 | I11: 4283 | J11: 0.00020567111 | K11: 51986 | L11: 0.0028631306 | M11: 8137 | N11: 0.00046510017 | O11: 13301 | P11: 0.00064151354 | Q11: 4471 | R11: 0.00023671901 | S11: 6920 | T11: 0.00037938322 | U11: 11868 | V11: 0.00072254678 | W11: 7234 | X11: 0.00052291796 | Y11: 6165 | Z11: 0.00042750452 | AA11: 6343 | AB11: 0.00036413736 | AC11: 5950 | AD11: 0.00044564431 | AE11: 10070 | AF11: 0.00083263989 | AG11: 7143 | AH11: 0.00043911015 | AI11: 3927 | AJ11: 0.00025164128 | AK11: 4716 | AL11: 0.00035709648 | AM11: 5081 | AN11: 0.00033513541 | AO11: 5506 | AP11: 0.00038520529 | AQ11: 0 | AR11: 0 | AS11: 4510 | AT11: 0.0003085485 | AU11: 3122 | AV11: 0.00020497917 | AW11: 4544 | AX11: 0.00030317836 | AY11: 6149 | AZ11: 0.00041001356 | BA11: 2333 | BB11: 0.00017012983 | BC11: 8720 | BD11: 0.00051242372 | BE11: 3668 | BF11: 0.00023157007 | BG11: 39788 | BH11: 0.0025371704 | BI11: 18447 | BJ11: 0.0010812421 | BK11: 4591 | BL11: 0.00031297055 | BM11: 5180 | BN11: 0.00035404932 | BO11: 13560 | BP11: 0.0009601401 | BQ11: 8254 | BR11: 0.00056997657 | BS11: 14522 | BT11: 0.0010754422 | BU11: 5670 | BV11: 0.00051750287 | BW11: 3636 | BX11: 0.00025711044 | BY11: 7055 | BZ11: 0.0005991396 | CA11: 8015 | CB11: 0.00052520241 | CC11: 26464 | CD11: 0.0023859039 | CE11: 13900 | CF11: 0.0010594893 | CG11: 3659 | CH11: 0.0002906254 | CI11: 4375 | CJ11: 0.00037296742 | CK11: 3553 | CL11: 0.00026353864 | CM11: 9868 | CN11: 0.00078405866 | CO11: 2091 | CP11: 0.00017003359 | CQ11: 9769 | CR11: 0.00076721253 | CS11: 6348 | CT11: 0.00056599095 | CU11: 14995 | CV11: 0.0010064391 | CW11: 14171 | CX11: 0.0011338257 | CY11: 10773 | CZ11: 0.0007812257 | DA11: 6560 | DB11: 0.0004268386 | DC11: 9297 | DD11: 0.00061028645 | DE11: 4926 | DF11: 0.00034719493 | DG11: 11550 | DH11: 0.00079243271 | DI11: 3731 | DJ11: 0.00025228377 | DK11: 5790 | DL11: 0.00040172527 | DM11: 14534 | DN11: 0.0010703845 | DO11: 13356 | DP11: 0.001212469 | DQ11: 3253 | DR11: 0.00024738547 | DS11: 2915 | DT11: 0.00022792845 | DU11: 1893 | DV11: 0.00015809756 | DW11: 12625 | DX11: 0.00099583061 | DY11: 8578 | DZ11: 0.00073425562 | EA11: 21093 | EB11: 0.0017336263 | EC11: 1573 | ED11: 0.00015521726 | EE11: 6500 | EF11: 0.00060785765 | EG11: 8115 | EH11: 0.00069800621 | EI11: 5579 | EJ11: 0.00046003436 | EK11: 8407 | EL11: 0.00074454005 | EM11: 40722 | EN11: 0.0046316074 | EO11: 8950 | EP11: 0.00093114258 | EQ11: 9436 | ER11: 0.00089894868 | ES11: =+$EY11 -> 16112 | ET11: =ES11/ES13 -> 0.0015891367 | EU11: =IF( SUM($EQ11:ES11)<0, "n/a", SUM($EQ11:ES11)/EU$74) -> 12774 | EV11: =EU11/EU13 -> 0.001238058 | EX11: AMB F | EY11: =IF(ISERROR(VLOOKUP(EX11,IQSH01E!$A$1:$M$400,2,0)),0,VLOOKUP(EX11,IQSH01E!$A$1:$M$400,2,0)) -> 16112 | EZ11: 1 space
B12: Reconsignment | C12: 0 | D12: 0 | E12: 0 | F12: 0 | G12: 0 | H12: 0 | I12: 0 | J12: 0 | K12: 0 | L12: 0 | M12: 0 | N12: 0 | O12: 0 | P12: 0 | Q12: 0 | R12: 0 | S12: 0 | T12: 0 | U12: 0 | V12: 0 | W12: 0 | X12: 0 | Y12: 0 | Z12: 0 | AA12: 0 | AB12: 0 | AC12: 0 | AD12: 0 | AE12: 0 | AF12: 0 | AG12: 0 | AH12: 0 | AI12: 0 | AJ12: 0 | AK12: 0 | AL12: 0 | AM12: 0 | AN12: 0 | AO12: 0 | AP12: 0 | AQ12: 0 | AR12: 0 | AS12: 0 | AT12: 0 | AU12: 0 | AV12: 0 | AW12: 0 | AX12: 0 | AY12: 0 | AZ12: 0 | BA12: 0 | BB12: 0 | BC12: 0 | BD12: 0 | BE12: 0 | BF12: 0 | BG12: 0 | BH12: 0 | BI12: 0 | BJ12: 0 | BK12: 0 | BL12: 0 | BM12: 0 | BN12: 0 | BO12: 0 | BP12: 0 | BQ12: 0 | BR12: 0 | BS12: 0 | BT12: 0 | BU12: 0 | BV12: 0 | BW12: 0 | BX12: 0 | BY12: 0 | BZ12: 0 | CA12: 0 | CB12: 0 | CC12: 0 | CD12: 0 | CE12: 0 | CF12: 0 | CG12: 0 | CH12: 0 | CI12: 0 | CJ12: 0 | CK12: 0 | CL12: 0 | CM12: 0 | CN12: 0 | CO12: 0 | CP12: 0 | CQ12: 0 | CR12: 0 | CS12: 0 | CT12: 0 | CU12: 0 | CV12: 0 | CW12: 0 | CX12: 0 | CY12: 0 | CZ12: 0 | DA12: 0 | DB12: 0 | DC12: 0 | DD12: 0 | DE12: 0 | DF12: 0 | DG12: 0 | DH12: 0 | DI12: 0 | DJ12: 0 | DK12: 0 | DL12: 0 | DM12: 0 | DN12: 0 | DO12: 0 | DP12: 0 | DQ12: 0 | DR12: 0 | DS12: 0 | DT12: 0 | DU12: 0 | DV12: 0 | DW12: 0 | DX12: 0 | DY12: 0 | DZ12: 0 | EA12: 0 | EB12: 0 | EC12: 0 | ED12: 0 | EE12: 0 | EF12: 0 | EG12: 0 | EH12: 0 | EI12: 0 | EJ12: 0 | EK12: 0 | EL12: 0 | EM12: 0 | EN12: 0 | EO12: 0 | EP12: 0 | EQ12: 0 | ER12: 0 | ES12: =+$EY12 -> 0 | ET12: =ES12/ES13 -> 0 | EU12: =IF( SUM($EQ12:ES12)<0, "n/a", SUM($EQ12:ES12)/EU$74) -> 0 | EV12: =EU12/EU13 -> 0 | EX12: AMBR | EY12: =IF(ISERROR(VLOOKUP(EX12,IQSH01E!$A$1:$M$400,2,0)),0,VLOOKUP(EX12,IQSH01E!$A$1:$M$400,2,0)) -> 0 | EZ12: no
B13: Prepaid Total | C13: 18983093 | D13: 1 | E13: 15937183 | F13: 1 | G13: 19209799 | H13: 1 | I13: 20824510 | J13: 1 | K13: 18157048 | L13: 1 | M13: 17495156 | N13: 1 | O13: 20733779 | P13: 1 | Q13: 18887372 | R13: 1 | S13: 18240132 | T13: 1 | U13: 16425234 | V13: 1 | W13: 13833910 | X13: 1 | Y13: 14420900 | Z13: 1 | AA13: 17419251 | AB13: 1 | AC13: 13351455 | AD13: 1 | AE13: 12094064 | AF13: 1 | AG13: 16266989 | AH13: 1 | AI13: 15605548 | AJ13: 1 | AK13: 13206515 | AL13: 1 | AM13: 15161036 | AN13: 1 | AO13: 14293677 | AP13: 1 | AQ13: 14883273 | AR13: 1 | AS13: 14616827 | AT13: 1 | AU13: 15230816 | AV13: 1 | AW13: 14987877 | AX13: 1 | AY13: 14997065 | AZ13: 1 | BA13: 13713057 | BB13: 1 | BC13: 17017167 | BD13: 1 | BE13: 15839698 | BF13: 1 | BG13: 15682037 | BH13: 1 | BI13: 17060934 | BJ13: 1 | BK13: 14669112 | BL13: 1 | BM13: 14630730 | BN13: 1 | BO13: 14122939 | BP13: 1 | BQ13: 14481297 | BR13: 1 | BS13: 13503283 | BT13: 1 | BU13: 10956461 | BV13: 1 | BW13: 14141783 | BX13: 1 | BY13: 11775219 | BZ13: 1 | CA13: 15260783 | CB13: 1 | CC13: 11091813 | CD13: 1 | CE13: 13119529 | CF13: 1 | CG13: 12590090 | CH13: 1 | CI13: 11730247 | CJ13: 1 | CK13: 13481894 | CL13: 1 | CM13: 12585793 | CN13: 1 | CO13: 12297570 | CP13: 1 | CQ13: 12733108 | CR13: 1 | CS13: 11215727 | CT13: 1 | CU13: 14899063 | CV13: 1 | CW13: 12498394 | CX13: 1 | CY13: 13789869 | CZ13: 1 | DA13: 15368807 | DB13: 1 | DC13: 15233830 | DD13: 1 | DE13: 14187995 | DF13: 1 | DG13: 14575370 | DH13: 1 | DI13: 14788902 | DJ13: 1 | DK13: 14412835 | DL13: 1 | DM13: 13578298 | DN13: 1 | DO13: 11015539 | DP13: 1 | DQ13: 13149519 | DR13: 1 | DS13: 12789101 | DT13: 1 | DU13: 11973619 | DV13: 1 | DW13: 12677859 | DX13: 1 | DY13: 11682580 | DZ13: 1 | EA13: 12166982 | EB13: 1 | EC13: 10134182 | ED13: 1 | EE13: 10693293 | EF13: 1 | EG13: 11625971 | EH13: 1 | EI13: 12127355 | EJ13: 1 | EK13: 11291535 | EL13: 1 | EM13: 8792196 | EN13: 1 | EO13: 9611847 | EP13: 1 | EQ13: 10496706 | ER13: 1 | ES13: =SUM(ES6:ES12) -> 10138838 | ET13: =ES13/ES13 -> 1 | EU13: =IF( SUM($EQ13:ES13)<0, "n/a", SUM($EQ13:ES13)/EU$74) -> 10317772 | EV13: =EU13/EU13 -> 1 | EX13: <--sub-total | EY13: =IF(ISERROR(VLOOKUP(EX13,IQSH01E!$A$1:$M$400,2,0)),0,VLOOKUP(EX13,IQSH01E!$A$1:$M$400,2,0)) -> 0
B14: CPU (Lolita) | C14: 5653768 | E14: 5544713 | G14: 6537194 | I14: 6810598 | K14: 6468231.6 | M14: 6883904 | O14: 7093821.1 | Q14: 6752947 | S14: 6957022 | U14: 5547692 | W14: 5691593 | Y14: 7519782 | AA14: 4467588 | AC14: 5335139 | AE14: 5036998 | AG14: 3770097 | AI14: 5012428 | AK14: 5158826 | AM14: 3942653 | AO14: 4801601 | AQ14: 5264835 | AS14: 4275476 | AU14: 5463657 | AW14: 5205630 | AY14: 5769592 | BA14: 5320721 | BC14: 5968050 | BE14: 4333602 | BG14: 4146596 | BI14: 6235083 | BK14: 4892717 | BM14: 6292716 | BO14: 6712833 | BQ14: 7063107 | BS14: 4910750 | BU14: 3536263 | BW14: 6248750 | BY14: 4791092 | CA14: 6513822 | CC14: 4132551 | CE14: 5057896 | CG14: 5039634 | CI14: 5148549 | CK14: 4985148 | CM14: 4845554 | CO14: 4091919 | CQ14: 4050275 | CS14: 3645604 | CU14: 5353062 | CW14: 4832196 | CY14: 4780282 | DA14: 5723074 | DC14: 5954916 | DE14: 6882780 | DG14: 7448846 | DI14: 7016144 | DK14: 6194991 | DM14: 6638684 | DO14: 4317570 | DQ14: 6258554 | DS14: 5581152 | DU14: 4725010 | DW14: 6125898 | DY14: 5972935 | EA14: 5014065 | EC14: 5587070 | EE14: 5956801 | EG14: 5075601 | EI14: 6272797 | EK14: 5766853 | EM14: 4161933 | EO14: 6147926 | EQ14: 7522103 | ES14: =+$EY14 -> 4855434 | EU14: =IF( SUM($EQ14:ES14)<0, "n/a", SUM($EQ14:ES14)/EU$74) -> 6188768.5 | EX14: AMB C | EY14: =IF(ISERROR(VLOOKUP(EX14,IQSH01E!$A$1:$M$400,2,0)),0,VLOOKUP(EX14,IQSH01E!$A$1:$M$400,2,0)) -> 4855434 | EZ14: 1 space
B15: Wharehouse | C15: 1117689 | E15: 908985 | G15: 1353690 | I15: 900528 | K15: 813322 | M15: 925838 | O15: 1262388 | Q15: 922899 | S15: 417839 | U15: 374329 | W15: 291822 | Y15: 422641 | AA15: 491368 | AC15: 496550 | AE15: 324991 | AG15: 704065 | AI15: 1034418 | AK15: 1035594 | AM15: 314992 | AO15: 221458 | AQ15: 381600 | AS15: 230857 | AU15: 581177 | AW15: 645572 | AY15: 899557 | BA15: 797185 | BC15: 1145458 | BE15: 884424 | BG15: 999199 | BI15: 1131623 | BK15: 1165090 | BM15: 1331563 | BO15: 953499 | BQ15: 1406257 | BS15: 1022813 | BU15: 1234312 | BW15: 1041298 | BY15: 1130394 | CA15: 1358598 | CC15: 1062974 | CE15: 789501 | CG15: 1424713 | CI15: 853728 | CK15: 1143529 | CM15: 931396 | CO15: 1304256 | CQ15: 1159200 | CS15: 770883 | CU15: 1148181 | CW15: 1190628 | CY15: 922059 | DA15: 1384194 | DC15: 1772736 | DE15: 1086206 | DG15: 1370164 | DI15: 1366852 | DK15: 951201 | DM15: 1323887 | DO15: 841083 | DQ15: 1219141 | DS15: 1256923 | DU15: 1214948 | DW15: 1231548 | DY15: 1331002 | EA15: 1295714 | EC15: 1573758 | EE15: 1453376 | EG15: 892725 | EI15: 1242189 | EK15: 1247196 | EM15: 694732 | EO15: 830698 | EQ15: 839845 | ES15: =+$EY15 -> 667697 | EU15: =IF( SUM($EQ15:ES15)<0, "n/a", SUM($EQ15:ES15)/EU$74) -> 753771 | EX15: AMB OS | EY15: =IF(ISERROR(VLOOKUP(EX15,IQSH01E!$A$1:$M$400,2,0)),0,VLOOKUP(EX15,IQSH01E!$A$1:$M$400,2,0)) -> 667697 | EZ15: 2 spaces
B16: Grand Total | C16: 25754550 | E16: 22390881 | G16: 27100683 | I16: 28535636 | K16: 25438602 | M16: 25304898 | O16: 29089988 | Q16: 26563218 | S16: 25614993 | U16: 22347255 | W16: 19817325 | Y16: 22363323 | AA16: 22378207 | AC16: 19183144 | AE16: 17456053 | AG16: 20741151 | AI16: 21652394 | AK16: 19400935 | AM16: 19418681 | AO16: 19316736 | AQ16: 20529708 | AS16: 19123160 | AU16: 21275650 | AW16: 20839079 | AY16: 21666214 | BA16: 19830963 | BC16: 24130675 | BE16: 21057724 | BG16: 20827832 | BI16: 24427640 | BK16: 20726919 | BM16: 22255009 | BO16: 21789271 | BQ16: 22950661 | BS16: 19436846 | BU16: 15727036 | BW16: 21431831 | BY16: 17696705 | CA16: 23133203 | CC16: 16287338 | CE16: 18966926 | CG16: 19054437 | CI16: 17732524 | CK16: 19610571 | CM16: 18362743 | CO16: 17693745 | CQ16: 17942583 | CS16: 15632214 | CU16: 21400306 | CW16: 18521218 | CY16: 19492210 | DA16: 22476075 | DC16: 22961482 | DE16: 22156981 | DG16: 23394380 | DI16: 23171898 | DK16: 21559027 | DM16: 21540869 | DO16: 16174192 | DQ16: 20627214 | DS16: 19627176 | DU16: 17913577 | DW16: 20035305 | DY16: 18986517 | EA16: 18476761 | EC16: 17295010 | EE16: 18103470 | EG16: 17594297 | EI16: 19642341 | EK16: 18305584 | EM16: 13648861 | EO16: 16590471 | EQ16: 18858654 | ES16: =SUM(ES13:ES15) -> 15661969 | EU16: =IF( SUM($EQ16:ES16)<0, "n/a", SUM($EQ16:ES16)/EU$74) -> 17260312 | EX16: AMB T | EY16: =IF(ISERROR(VLOOKUP(EX16,IQSH01E!$A$1:$M$400,2,0)),0,VLOOKUP(EX16,IQSH01E!$A$1:$M$400,2,0)) -> 15661969 | EZ16: 1 space
B17: Intermodal | C17: 186858 | D17: 0.010327842 | E17: 484266 | F17: 0.027981993 | G17: 226131 | H17: 0.013327004 | I17: 151404 | J17: 0.011655996 | K17: 0 | L17: 0 | M17: 146479 | N17: 0.010083039 | O17: 75917 | P17: 0.004413117 | Q17: 205969 | R17: 0.012720415 | S17: 183644 | T17: 0.009907815 | U17: 35268 | V17: 0.0019086214 | W17: 0 | X17: 0 | Y17: 0 | Z17: 0 | AA17: 76557 | AB17: 0.0042079204 | AC17: 96188 | AD17: 0.0063729918 | AE17: 74898 | AF17: 0.0035289073 | AG17: 38157 | AH17: 0.0020129424 | AI17: 38400 | AJ17: 0.002429303 | AK17: 33998 | AL17: 0.0016353544 | AM17: 0 | AN17: 0 | AO17: 38586 | AP17: 0.0020451065 | AQ17: 0 | AR17: 0 | AS17: 0 | AT17: 0 | AU17: 0 | AV17: 0 | AW17: 0 | AX17: 0 | AY17: 0 | AZ17: 0 | BA17: 0 | BB17: 0 | BC17: 0 | BD17: 0 | BE17: 0 | BF17: 0 | BG17: 0 | BH17: 0 | BI17: 0 | BJ17: 0 | BK17: 0 | BL17: 0 | BM17: 0 | BN17: 0 | BO17: 0 | BP17: 0 | BQ17: 0 | BR17: 0 | BS17: 0 | BT17: 0 | BU17: 0 | BV17: 0 | BW17: 0 | BX17: 0 | BY17: 0 | BZ17: 0 | CA17: 0 | CB17: 0 | CC17: 0 | CD17: 0 | CE17: 0 | CF17: 0 | CG17: 0 | CH17: 0 | CI17: 0 | CJ17: 0 | CK17: 0 | CL17: 0 | CM17: 0 | CN17: 0 | CO17: 0 | CP17: 0 | CQ17: 0 | CR17: 0 | CS17: 0 | CT17: 0 | CU17: 0 | CV17: 0 | CW17: 0 | CX17: 0 | CY17: 0 | CZ17: 0 | DA17: 0 | DB17: 0 | DC17: 0 | DD17: 0 | DE17: 0 | DF17: 0 | DG17: 0 | DH17: 0 | DI17: 0 | DJ17: 0 | DK17: 0 | DL17: 0 | DM17: 0 | DN17: 0 | DO17: 0 | DP17: 0 | DQ17: 0 | DR17: 0 | DS17: 0 | DT17: 0 | DU17: 0 | DV17: 0 | DW17: 0 | DX17: 0 | DY17: 0 | DZ17: 0 | EA17: 0 | EB17: 0 | EC17: 0 | ED17: 0 | EE17: 0 | EF17: 0 | EG17: 0 | EH17: 0 | EI17: 0 | EJ17: 0 | EK17: 0 | EL17: 0 | EM17: 0 | EN17: 0 | EO17: 0 | EP17: 0 | EQ17: 0 | ER17: 0 | ES17: =+$EY17 -> 0 | ET17: =ES17/ES24 -> 0 | EU17: =IF( SUM($EQ17:ES17)<0, "n/a", SUM($EQ17:ES17)/EU$74) -> 0 | EV17: =EU17/EU24 -> 0 | EX17: AMWI | EY17: =IF(ISERROR(VLOOKUP(EX17,IQSH01E!$A$1:$M$400,2,0)),0,VLOOKUP(EX17,IQSH01E!$A$1:$M$400,2,0)) -> 0 | EZ17: no
B18: FTL | C18: 16202369 | D18: 0.89552231 | E18: 15321663 | F18: 0.88532058 | G18: 14833165 | H18: 0.87419083 | I18: 11334155 | J18: 0.87257184 | K18: 11060999 | L18: 0.90090304 | M18: 12905142 | N18: 0.8883393 | O18: 15596671 | P18: 0.90664718 | Q18: 14296036 | R18: 0.8829072 | S18: 16351936 | T18: 0.88220663 | U18: 16306751 | V18: 0.88248312 | W18: 13344124 | X18: 0.88404041 | Y18: 13012979 | Z18: 0.87836512 | AA18: 16403168 | AB18: 0.90159259 | AC18: 13307694 | AD18: 0.88170902 | AE18: 19168222 | AF18: 0.90313329 | AG18: 17504933 | AH18: 0.92345889 | AI18: 14429543 | AJ18: 0.91285762 | AK18: 18762586 | AL18: 0.90250834 | AM18: 17478652 | AN18: 0.90548228 | AO18: 17000715 | AP18: 0.90105926 | AQ18: 18288450 | AR18: 0.91473364 | AS18: 17054962 | AT18: 0.93545603 | AU18: 15047202 | AV18: 0.91908125 | AW18: 14251929 | AX18: 0.9155464 | AY18: 16930063 | AZ18: 0.92763727 | BA18: 14859222 | BB18: 0.92940123 | BC18: 20820667 | BD18: 0.94411331 | BE18: 18346818 | BF18: 0.92894917 | BG18: 17193174 | BH18: 0.93131157 | BI18: 18760702 | BJ18: 0.93415602 | BK18: 14170368 | BL18: 0.9170147 | BM18: 17168359 | BN18: 0.92627738 | BO18: 15865199 | BP18: 0.93051453 | BQ18: 16568542 | BR18: 0.93303938 | BS18: 15537558 | BT18: 0.93353429 | BU18: 14339897 | BV18: 0.93815186 | BW18: 15806641 | BX18: 0.93286258 | BY18: 16597934 | BZ18: 0.93213028 | CA18: 19408378 | CB18: 0.93054191 | CC18: 14889383 | CD18: 0.93151917 | CE18: 14348764 | CF18: 0.92521128 | CG18: 16335198 | CH18: 0.92295449 | CI18: 14924384 | CJ18: 0.92647602 | CK18: 18249206 | CL18: 0.93637804 | CM18: 17385848 | CN18: 0.94760381 | CO18: 18448196 | CP18: 0.94036673 | CQ18: 15618242 | CR18: 0.9403084 | CS18: 14822894 | CT18: 0.93647006 | CU18: 18128494 | CV18: 0.93650583 | CW18: 17859805 | CX18: 0.93398558 | CY18: 16565103 | CZ18: 0.93104342 | DA18: 17236724 | DB18: 0.91474835 | DC18: 16678212 | DD18: 0.92209995 | DE18: 16015613 | DF18: 0.90600543 | DG18: 16219400 | DH18: 0.90958548 | DI18: 17128204 | DJ18: 0.90863122 | DK18: 14713928 | DL18: 0.91061109 | DM18: 16626904 | DN18: 0.89644056 | DO18: 14147610 | DP18: 0.90483143 | DQ18: 15342336 | DR18: 0.89411741 | DS18: 17089312 | DT18: 0.88807428 | DU18: 15385849 | DV18: 0.88372919 | DW18: 15552987 | DX18: 0.88525191 | DY18: 15156775 | DZ18: 0.89348886 | EA18: 14926615 | EB18: 0.89106104 | EC18: 15369478 | ED18: 0.91415057 | EE18: 17457504 | EF18: 0.91880927 | EG18: 16240192 | EH18: 0.91320857 | EI18: 14738498 | EJ18: 0.90120972 | EK18: 15694523 | EL18: 0.90480831 | EM18: 13423745 | EN18: 0.91630124 | EO18: 16026055 | EP18: 0.91286962 | EQ18: 16171920 | ER18: 0.91433363 | ES18: =+$EY18 -> 16294411 | ET18: =ES18/ES24 -> 0.92646299 | EU18: =IF( SUM($EQ18:ES18)<0, "n/a", SUM($EQ18:ES18)/EU$74) -> 16233166 | EV18: =EU18/EU24 -> 0.92038123 | EX18: All Others | EY18: =+EY27-EY26-EY25-EY17-EY20-EY21-EY22-EY23-EY19 -> 16294411
B19: Railcar | C19: 0 | D19: 0 | E19: 0 | F19: 0 | G19: 0 | H19: 0 | I19: 0 | J19: 0 | K19: 0 | L19: 0 | M19: 0 | N19: 0 | O19: 0 | P19: 0 | Q19: 0 | R19: 0 | S19: 0 | T19: 0 | U19: 0 | V19: 0 | W19: 0 | X19: 0 | Y19: 0 | Z19: 0 | AA19: 0 | AB19: 0 | AC19: 0 | AD19: 0 | AE19: 0 | AF19: 0 | AG19: 0 | AH19: 0 | AI19: 0 | AJ19: 0 | AK19: 0 | AL19: 0 | AM19: 0 | AN19: 0 | AO19: 0 | AP19: 0 | AQ19: 0 | AR19: 0 | AS19: 0 | AT19: 0 | AU19: 0 | AV19: 0 | AW19: 0 | AX19: 0 | AY19: 0 | AZ19: 0 | BA19: 0 | BB19: 0 | BC19: 0 | BD19: 0 | BE19: 0 | BF19: 0 | BG19: 0 | BH19: 0 | BI19: 0 | BJ19: 0 | BK19: 0 | BL19: 0 | BM19: 0 | BN19: 0 | BO19: 0 | BP19: 0 | BQ19: 0 | BR19: 0 | BS19: 0 | BT19: 0 | BU19: 0 | BV19: 0 | BW19: 0 | BX19: 0 | BY19: 0 | BZ19: 0 | CA19: 0 | CB19: 0 | CC19: 0 | CD19: 0 | CE19: 0 | CF19: 0 | CG19: 0 | CH19: 0 | CI19: 0 | CJ19: 0 | CK19: 0 | CL19: 0 | CM19: 0 | CN19: 0 | CO19: 0 | CP19: 0 | CQ19: 0 | CR19: 0 | CS19: 0 | CT19: 0 | CU19: 0 | CV19: 0 | CW19: 0 | CX19: 0 | CY19: 0 | CZ19: 0 | DA19: 0 | DB19: 0 | DC19: 0 | DD19: 0 | DE19: 0 | DF19: 0 | DG19: 0 | DH19: 0 | DI19: 0 | DJ19: 0 | DK19: 0 | DL19: 0 | DM19: 0 | DN19: 0 | DO19: 0 | DP19: 0 | DQ19: 0 | DR19: 0 | DS19: 0 | DT19: 0 | DU19: 0 | DV19: 0 | DW19: 0 | DX19: 0 | DY19: 0 | DZ19: 0 | EA19: 0 | EB19: 0 | EC19: 0 | ED19: 0 | EE19: 0 | EF19: 0 | EG19: 0 | EH19: 0 | EI19: 0 | EJ19: 0 | EK19: 0 | EL19: 0 | EM19: 0 | EN19: 0 | EO19: 0 | EP19: 0 | EQ19: 0 | ER19: 0 | ES19: =+$EY19 -> 0 | ET19: =ES19/ES24 -> 0 | EU19: =IF( SUM($EQ19:ES19)<0, "n/a", SUM($EQ19:ES19)/EU$74) -> 0 | EV19: =EU19/EU24 -> 0 | EX19: AMW RC | EY19: =IF(ISERROR(VLOOKUP(EX19,IQSH01E!$A$1:$M$400,2,0)),0,VLOOKUP(EX19,IQSH01E!$A$1:$M$400,2,0)) -> 0 | EZ19: 2 spaces
B20: LTL | C20: 1562031.4 | D20: 0.08633515 | E20: 1367145.9 | F20: 0.078996806 | G20: 1704613.6 | H20: 0.10046121 | I20: 1328700.3 | J20: 0.10229138 | K20: 1137361.9 | L20: 0.092636551 | M20: 1280980.4 | N20: 0.088177664 | O20: 1381909.3 | P20: 0.08033151 | Q20: 1461765.9 | R20: 0.090277023 | S20: 1951290 | T20: 0.10527444 | U20: 1892452.7 | V20: 0.1024151 | W20: 1606212.5 | X20: 0.10641064 | Y20: 1571705.8 | Z20: 0.10608882 | AA20: 1678014.4 | AB20: 0.092231293 | AC20: 1515205.9 | AD20: 0.10039085 | AE20: 1846255.3 | AF20: 0.08698849 | AG20: 1221785.3 | AH20: 0.064454316 | AI20: 1252015.6 | AJ20: 0.079206385 | AK20: 1670968.5 | AL20: 0.080376073 | AM20: 1678964.5 | AN20: 0.086978821 | AO20: 1668281.2 | AP20: 0.088421003 | AQ20: 1482770.2 | AR20: 0.074163737 | AS20: 1090485.7 | AT20: 0.059812591 | AU20: 1134816.1 | AV20: 0.069314428 | AW20: 1157576.9 | AX20: 0.074362942 | AY20: 1194785.6 | AZ20: 0.06546506 | BA20: 912830.85 | BB20: 0.05709492 | BC20: 1195174 | BD20: 0.054195173 | BE20: 1124464.4 | BF20: 0.056934687 | BG20: 1167407.6 | BH20: 0.063235571 | BI20: 1240230 | BJ20: 0.061755062 | BK20: 1218844.2 | BL20: 0.078875723 | BM20: 1315311.3 | BN20: 0.070964445 | BO20: 1138683.4 | BP20: 0.066785262 | BQ20: 1160871.1 | BR20: 0.065373191 | BS20: 1105640 | BT20: 0.066429543 | BU20: 923280.52 | BV20: 0.060403315 | BW20: 1060205.4 | BX20: 0.062570276 | BY20: 1139234.5 | BZ20: 0.063978743 | CA20: 1426089 | CB20: 0.068374367 | CC20: 1028040.6 | CD20: 0.064316936 | CE20: 1080440.4 | CF20: 0.069667025 | CG20: 1362353.6 | CH20: 0.076974292 | CI20: 1109401.2 | CJ20: 0.068869419 | CK20: 1160322.8 | CL20: 0.059536879 | CM20: 959779.95 | CN20: 0.052312152 | CO20: 1128327.9 | CP20: 0.057514674 | CQ20: 990738.83 | CR20: 0.059648201 | CS20: 991717.03 | CT20: 0.062653981 | CU20: 1190640 | CV20: 0.061507663 | CW20: 1223365.1 | CX20: 0.063976363 | CY20: 1221160.4 | CZ20: 0.068635452 | DA20: 1605444.1 | DB20: 0.08520049 | DC20: 1405548.1 | DD20: 0.07770952 | DE20: 1656590.5 | DF20: 0.09371355 | DG20: 1610194 | DH20: 0.090299831 | DI20: 1721248 | DJ20: 0.091310196 | DK20: 1437684 | DL20: 0.088974949 | DM20: 1916642 | DN20: 0.10333587 | DO20: 1475904 | DP20: 0.094393634 | DQ20: 1815817 | DR20: 0.1058218 | DS20: 2151566 | DT20: 0.11180968 | DU20: 2023181 | DV20: 0.11620705 | DW20: 2002047 | DX20: 0.11395341 | DY20: 1806258 | DZ20: 0.10647855 | EA20: 1824333 | EB20: 0.10890561 | EC20: 1442628 | ED20: 0.085805075 | EE20: 1540010 | EF20: 0.081052565 | EG20: 1514154 | EH20: 0.085142984 | EI20: 1523091 | EJ20: 0.093131906 | EK20: 1570494 | EL20: 0.090540886 | EM20: 1217687 | EN20: 0.083118988 | EO20: 1388073 | EP20: 0.079066849 | EQ20: 1505310 | ER20: 0.08510774 | ES20: =+$EY20 -> 1291440 | ET20: =ES20/ES24 -> 0.073428328 | EU20: =IF( SUM($EQ20:ES20)<0, "n/a", SUM($EQ20:ES20)/EU$74) -> 1398375 | EV20: =EU20/EU24 -> 0.079284481 | EX20: AMW L | EY20: =IF(ISERROR(VLOOKUP(EX20,IQSH01E!$A$1:$M$400,2,0)),0,VLOOKUP(EX20,IQSH01E!$A$1:$M$400,2,0)) -> 1291440 | EZ20: 1 space
B21: Export | C21: 133295 | D21: 0.0073673575 | E21: 110892 | F21: 0.0064075925 | G21: 188359 | H21: 0.011100916 | I21: 172824 | J21: 0.013305037 | K21: 77504 | L21: 0.0063125935 | M21: 188310 | N21: 0.012962521 | O21: 147113 | P21: 0.0085517984 | Q21: 209637 | R21: 0.012946947 | S21: 15799 | T21: 0.00085237508 | U21: 240928 | V21: 0.013038458 | W21: 143564 | X21: 0.0095110313 | Y21: 210074 | Z21: 0.014179818 | AA21: 25040 | AB21: 0.0013763121 | AC21: 173212 | AD21: 0.011476262 | AE21: 129694 | AF21: 0.0061106853 | AG21: 190698 | AH21: 0.010060122 | AI21: 83560 | AJ21: 0.0052862646 | AK21: 320454 | AL21: 0.015414315 | AM21: 139364 | AN21: 0.0072197575 | AO21: 158630 | AP21: 0.0084075895 | AQ21: 212681 | AR21: 0.010637668 | AS21: 61588 | AT21: 0.0033780707 | AU21: 189157 | AV21: 0.011553686 | AW21: 116144 | AX21: 0.007461111 | AY21: 124606 | AZ21: 0.0068274505 | BA21: 213960 | BB21: 0.013382577 | BC21: 34124 | BD21: 0.001547353 | BE21: 277758 | BF21: 0.014063641 | BG21: 100263 | BH21: 0.0054309978 | BI21: 80580 | BJ21: 0.0040123388 | BK21: 25040 | BL21: 0.0016204271 | BM21: 34048 | BN21: 0.0018369777 | BO21: 22805 | BP21: 0.0013375429 | BQ21: 22728 | BR21: 0.0012799025 | BS21: 0 | BT21: 0 | BU21: 21280 | BV21: 0.0013921907 | BW21: 61672 | BX21: 0.0036397044 | BY21: 44920 | BZ21: 0.0025226809 | CA21: 21768 | CB21: 0.0010436749 | CC21: 65104 | CD21: 0.0040730783 | CE21: 42066 | CF21: 0.0027124245 | CG21: 0 | CH21: 0 | CI21: 73738 | CJ21: 0.0045775082 | CK21: 75904 | CL21: 0.0038946811 | CM21: 0 | CN21: 0 | CO21: 39624 | CP21: 0.0020197688 | CQ21: 0 | CR21: 0 | CS21: 0 | CT21: 0 | CU21: 37952 | CV21: 0.0019605748 | CW21: 37952 | CX21: 0.0019847149 | CY21: 0 | CZ21: 0 | DA21: 0 | DB21: 0 | DC21: 0 | DD21: 0 | DE21: 0 | DF21: 0 | DG21: 0 | DH21: 0 | DI21: 0 | DJ21: 0 | DK21: 0 | DL21: 0 | DM21: 0 | DN21: 0 | DO21: 0 | DP21: 0 | DQ21: 0 | DR21: 0 | DS21: 0 | DT21: 0 | DU21: 0 | DV21: 0 | DW21: 12610 | DX21: 0.00071774165 | DY21: 0 | DZ21: 0 | EA21: 0 | EB21: 0 | EC21: 0 | ED21: 0 | EE21: 0 | EF21: 0 | EG21: 0 | EH21: 0 | EI21: 79839 | EJ21: 0.0048818871 | EK21: 73809 | EL21: 0.0042551785 | EM21: 0 | EN21: 0 | EO21: 114913 | EP21: 0.0065456276 | EQ21: 0 | ER21: 0 | ES21: =+$EY21 -> 0 | ET21: =ES21/ES24 -> 0 | EU21: =IF( SUM($EQ21:ES21)<0, "n/a", SUM($EQ21:ES21)/EU$74) -> 0 | EV21: =EU21/EU24 -> 0 | EX21: AMWE | EY21: =IF(ISERROR(VLOOKUP(EX21,IQSH01E!$A$1:$M$400,2,0)),0,VLOOKUP(EX21,IQSH01E!$A$1:$M$400,2,0)) -> 0 | EZ21: no
A22: SW | B22: Sample | C22: 8093.56 | D22: 0.00044733974 | E22: 9600.51 | F22: 0.00055473935 | G22: 784.12 | H22: 4.621202e-05 | I22: 2282.82 | J22: 0.0001757453 | K22: 1814.88 | L22: 0.00014781946 | M22: 567.33 | N22: 3.905277e-05 | O22: 970.09 | P22: 5.6392121e-05 | Q22: 1071.21 | R22: 6.6156731e-05 | S22: 1286.66 | T22: 6.9416857e-05 | U22: 2858.46 | V22: 0.00015469315 | W22: 572.31 | X22: 3.7915204e-05 | Y22: 388.76 | Z22: 2.6240973e-05 | AA22: 1868.42 | AB22: 0.00010269685 | AC22: 767.93 | AD22: 5.0879648e-05 | AE22: 696.58 | AF22: 3.2820186e-05 | AG22: 260.26 | AH22: 1.3729811e-05 | AI22: 1825.25 | AJ22: 0.00011547097 | AK22: 1370.49 | AL22: 6.592261e-05 | AM22: 4501.6 | AN22: 0.00023320557 | AO22: 1264.87 | AP22: 6.7039701e-05 | AQ22: 368 | AR22: 1.8406261e-05 | AS22: 953.16 | AT22: 5.2280344e-05 | AU22: 829.07 | AV22: 5.0639493e-05 | AW22: 40933.07 | AX22: 0.0026295476 | AY22: 1281.57 | AZ22: 7.022018e-05 | BA22: 1938.85 | BB22: 0.00012126944 | BC22: 1520.32 | BD22: 6.8938921e-05 | BE22: 1036.89 | BF22: 5.2500555e-05 | BG22: 403.58 | BH22: 2.1860927e-05 | BI22: 1537.98 | BJ22: 7.6580999e-05 | BK22: 36000.16 | BL22: 0.0023296979 | BM22: 17074.27 | BN22: 0.00092120103 | BO22: 23233.31 | BP22: 0.0013626638 | BQ22: 5460.86 | BR22: 0.00030752238 | BS22: 601.99 | BT22: 3.6169025e-05 | BU22: 804.52 | BV22: 5.2633705e-05 | BW22: 4118.73 | BX22: 0.00024307562 | BY22: 1172.52 | BZ22: 6.5848036e-05 | CA22: 835.28 | CB22: 4.0047811e-05 | CC22: 1451.6 | CD22: 9.0815932e-05 | CE22: 37364.43 | CF22: 0.0024092663 | CG22: 1260.56 | CH22: 7.1222857e-05 | CI22: 1241.23 | CJ22: 7.7053086e-05 | CK22: 3710.8 | CL22: 0.00019040344 | CM22: 1541.95 | CN22: 8.4042934e-05 | CO22: 1938.87 | CP22: 9.8830738e-05 | CQ22: 720.83 | CR22: 4.339813e-05 | CS22: 13865.03 | CT22: 0.00087595483 | CU22: 501.99 | CV22: 2.5932466e-05 | CW22: 1020.1 | CX22: 5.3346534e-05 | CY22: 5713.42 | CZ22: 0.0003211234 | DA22: 963.93 | DB22: 5.1155509e-05 | DC22: 3446.19 | DD22: 0.00019053191 | DE22: 3687.72 | DF22: 0.00020861482 | DG22: 2045.15 | DH22: 0.0001146922 | DI22: 1104.34 | DJ22: 5.8583947e-05 | DK22: 6688.85 | DL22: 0.00041395751 | DM22: 4146.74 | DN22: 0.00022357174 | DO22: 1136.69 | DP22: 7.2698698e-05 | DQ22: 1043.12 | DR22: 6.0790727e-05 | DS22: 2232.99 | DT22: 0.00011604101 | DU22: 1110.03 | DV22: 6.3757672e-05 | DW22: 1351.78 | DX22: 7.6941222e-05 | DY22: 552.92 | DZ22: 3.2594524e-05 | EA22: 558.76 | EB22: 3.3355805e-05 | EC22: 745.76 | ED22: 4.4356544e-05 | EE22: 2625.08 | EF22: 0.00013816109 | EG22: 7894.4 | EH22: 0.00044391309 | EI22: 12698.77 | EJ22: 0.00077648719 | EK22: 1786.98 | EL22: 0.00010302157 | EM22: 927.61 | EN22: 6.331841e-05 | EO22: 26647.79 | EP22: 0.0015179006 | EQ22: 9880.49 | ER22: 0.00055862658 | ES22: =+$EY22 -> 1911.52 | ET22: =ES22/ES24 -> 0.00010868466 | EU22: =IF( SUM($EQ22:ES22)<0, "n/a", SUM($EQ22:ES22)/EU$74) -> 5896.0053 | EV22: =EU22/EU24 -> 0.00033428923 | EX22: AMW F | EY22: =IF(ISERROR(VLOOKUP(EX22,IQSH01E!$A$1:$M$400,2,0)),0,VLOOKUP(EX22,IQSH01E!$A$1:$M$400,2,0)) -> 1911.52 | EZ22: 1 space
B23: Reconsignment | C23: 0 | D23: 0 | E23: 12777 | F23: 0.00073828418 | G23: 14827.06 | H23: 0.00087383104 | I23: 0 | J23: 0 | K23: 0 | L23: 0 | M23: 5788 | N23: 0.0003984232 | O23: 0 | P23: 0 | Q23: 17524 | R23: 0.0010822626 | S23: 31312 | T23: 0.0016893201 | U23: 0 | V23: 0 | W23: 0 | X23: 0 | Y23: 19852 | Z23: 0.0013399933 | AA23: 8900 | AB23: 0.00048918442 | AC23: 0 | AD23: 0 | AE23: 4368 | AF23: 0.00020580345 | AG23: 0 | AH23: 0 | AI23: 1659 | AJ23: 0.00010495348 | AK23: 0 | AL23: 0 | AM23: 1658.88 | AN23: 8.5938344e-05 | AO23: 0 | AP23: 0 | AQ23: 8928 | AR23: 0.00044655189 | AS23: 23720 | AT23: 0.00130103 | AU23: 0 | AV23: 0 | AW23: 0 | AX23: 0 | AY23: 0 | AZ23: 0 | BA23: 0 | BB23: 0 | BC23: 1659 | BD23: 7.5227366e-05 | BE23: 0 | BF23: 0 | BG23: 0 | BH23: 0 | BI23: 0 | BJ23: 0 | BK23: 2464 | BL23: 0.00015945417 | BM23: 0 | BN23: 0 | BO23: 0 | BP23: 0 | BQ23: 0 | BR23: 0 | BS23: 0 | BT23: 0 | BU23: 0 | BV23: 0 | BW23: 11596 | BX23: 0.00068436262 | BY23: 23192 | BZ23: 0.0013024491 | CA23: 0 | CB23: 0 | CC23: 0 | CD23: 0 | CE23: 0 | CF23: 0 | CG23: 0 | CH23: 0 | CI23: 0 | CJ23: 0 | CK23: 0 | CL23: 0 | CM23: 0 | CN23: 0 | CO23: 0 | CP23: 0 | CQ23: 0 | CR23: 0 | CS23: 0 | CT23: 0 | CU23: 0 | CV23: 0 | CW23: 0 | CX23: 0 | CY23: 0 | CZ23: 0 | DA23: 0 | DB23: 0 | DC23: 0 | DD23: 0 | DE23: 1280 | DF23: 7.2409773e-05 | DG23: 0 | DH23: 0 | DI23: 0 | DJ23: 0 | DK23: 0 | DL23: 0 | DM23: 0 | DN23: 0 | DO23: 10980 | DP23: 0.00070224222 | DQ23: 0 | DR23: 0 | DS23: 0 | DT23: 0 | DU23: 0 | DV23: 0 | DW23: 0 | DX23: 0 | DY23: 0 | DZ23: 0 | EA23: 0 | EB23: 0 | EC23: 0 | ED23: 0 | EE23: 0 | EF23: 0 | EG23: 21421 | EH23: 0.0012045326 | EI23: 0 | EJ23: 0 | EK23: 5075.49 | EL23: 0.00029260816 | EM23: 7566 | EN23: 0.00051645313 | EO23: 0 | EP23: 0 | EQ23: 0 | ER23: 0 | ES23: =+$EY23 -> 0 | ET23: =ES23/ES24 -> 0 | EU23: =IF( SUM($EQ23:ES23)<0, "n/a", SUM($EQ23:ES23)/EU$74) -> 0 | EV23: =EU23/EU24 -> 0 | EX23: AMWR | EY23: =IF(ISERROR(VLOOKUP(EX23,IQSH01E!$A$1:$M$400,2,0)),0,VLOOKUP(EX23,IQSH01E!$A$1:$M$400,2,0)) -> 0 | EZ23: no
B24: Prepaid Total | C24: 18092647 | D24: 1 | E24: 17306344 | F24: 1 | G24: 16967880 | H24: 1 | I24: 12989366 | J24: 1 | K24: 12277680 | L24: 1 | M24: 14527267 | N24: 1 | O24: 17202581 | P24: 1 | Q24: 16192003 | R24: 1 | S24: 18535267 | T24: 1 | U24: 18478258 | V24: 1 | W24: 15094472 | X24: 1 | Y24: 14814999 | Z24: 1 | AA24: 18193548 | AB24: 1 | AC24: 15093068 | AD24: 1 | AE24: 21224134 | AF24: 1 | AG24: 18955833 | AH24: 1 | AI24: 15807003 | AJ24: 1 | AK24: 20789377 | AL24: 1 | AM24: 19303141 | AN24: 1 | AO24: 18867477 | AP24: 1 | AQ24: 19993197 | AR24: 1 | AS24: 18231709 | AT24: 1 | AU24: 16372004 | AV24: 1 | AW24: 15566582 | AX24: 1 | AY24: 18250737 | AZ24: 1 | BA24: 15987952 | BB24: 1 | BC24: 22053145 | BD24: 1 | BE24: 19750077 | BF24: 1 | BG24: 18461248 | BH24: 1 | BI24: 20083050 | BJ24: 1 | BK24: 15452716 | BL24: 1 | BM24: 18534793 | BN24: 1 | BO24: 17049921 | BP24: 1 | BQ24: 17757602 | BR24: 1 | BS24: 16643800 | BT24: 1 | BU24: 15285263 | BV24: 1 | BW24: 16944233 | BX24: 1 | BY24: 17806454 | BZ24: 1 | CA24: 20857070 | CB24: 1 | CC24: 15983980 | CD24: 1 | CE24: 15508634 | CF24: 1 | CG24: 17698813 | CH24: 1 | CI24: 16108764 | CJ24: 1 | CK24: 19489144 | CL24: 1 | CM24: 18347170 | CN24: 1 | CO24: 19618087 | CP24: 1 | CQ24: 16609702 | CR24: 1 | CS24: 15828476 | CT24: 1 | CU24: 19357588 | CV24: 1 | CW24: 19122142 | CX24: 1 | CY24: 17791976 | CZ24: 1 | DA24: 18843132 | DB24: 1 | DC24: 18087206 | DD24: 1 | DE24: 17677172 | DF24: 1 | DG24: 17831639 | DH24: 1 | DI24: 18850556 | DJ24: 1 | DK24: 16158301 | DL24: 1 | DM24: 18547693 | DN24: 1 | DO24: 15635631 | DP24: 1 | DQ24: 17159196 | DR24: 1 | DS24: 19243111 | DT24: 1 | DU24: 17410140 | DV24: 1 | DW24: 17568996 | DX24: 1 | DY24: 16963586 | DZ24: 1 | EA24: 16751507 | EB24: 1 | EC24: 16812852 | ED24: 1 | EE24: 19000139 | EF24: 1 | EG24: 17783661 | EH24: 1 | EI24: 16354127 | EJ24: 1 | EK24: 17345688 | EL24: 1 | EM24: 14649926 | EN24: 1 | EO24: 17555689 | EP24: 1 | EQ24: 17687110 | ER24: 1 | ES24: =SUM(ES17:ES23) -> 17587763 | ET24: =ES24/ES24 -> 1 | EU24: =IF( SUM($EQ24:ES24)<0, "n/a", SUM($EQ24:ES24)/EU$74) -> 17637437 | EV24: =EU24/EU24 -> 1 | EX24: <--sub-total | EY24: =IF(ISERROR(VLOOKUP(EX24,IQSH01E!$A$1:$M$400,2,0)),0,VLOOKUP(EX24,IQSH01E!$A$1:$M$400,2,0)) -> 0
B25: CPU (Lolita) | C25: 893728.52 | E25: 786606.78 | G25: 673124.24 | I25: 628177 | K25: 644433.76 | M25: 822100.75 | O25: 620435 | Q25: 497795 | S25: 718634.32 | U25: 770340.39 | W25: 468678 | Y25: 727137.8 | AA25: 872419.45 | AC25: 603396 | AE25: 751557 | AG25: 330451.33 | AI25: 318268 | AK25: 753966 | AM25: 595369 | AO25: 627756 | AQ25: 473744.6 | AS25: 554924.8 | AU25: 774488.85 | AW25: 426515 | AY25: 548575.75 | BA25: 634314.84 | BC25: 1004928 | BE25: 522233.35 | BG25: 695655 | BI25: 717600.3 | BK25: 793738.8 | BM25: 793099.18 | BO25: 753944 | BQ25: 793586 | BS25: 525704 | BU25: 668393 | BW25: 636427 | BY25: 561613 | CA25: 777161.2 | CC25: 595122 | CE25: 544950 | CG25: 662867 | CI25: 632718 | CK25: 560043 | CM25: 775281 | CO25: 541911 | CQ25: 677146 | CS25: 392667.87 | CU25: 714243 | CW25: 558949 | CY25: 714536 | DA25: 667426 | DC25: 633530 | DE25: 533467 | DG25: 697743.98 | DI25: 652017 | DK25: 563428 | DM25: 627842 | DO25: 500326 | DQ25: 624083.24 | DS25: 642999 | DU25: 668314 | DW25: 482361 | DY25: 574408 | EA25: 525550 | EC25: 583534 | EE25: 861893 | EG25: 776624 | EI25: 950217 | EK25: 898016.49 | EM25: 608623 | EO25: 750750 | EQ25: 556123 | ES25: =+$EY25 -> 592413 | EU25: =IF( SUM($EQ25:ES25)<0, "n/a", SUM($EQ25:ES25)/EU$74) -> 574268 | EX25: AMW C | EY25: =IF(ISERROR(VLOOKUP(EX25,IQSH01E!$A$1:$M$400,2,0)),0,VLOOKUP(EX25,IQSH01E!$A$1:$M$400,2,0)) -> 592413 | EZ25: 1 space
B26: Wharehouse | C26: 129287 | E26: 97515 | G26: 121385 | I26: 53965 | K26: 34849 | M26: 230918 | O26: 174306 | Q26: 96785 | S26: 117620.52 | U26: 78316.96 | W26: 57532 | Y26: 99256 | AA26: 295787 | AC26: 159679 | AE26: 21211 | AG26: 230381 | AI26: 228826 | AK26: 64303 | AM26: 258096 | AO26: 0 | AQ26: 0 | AS26: 0 | AU26: 0 | AW26: 0 | AY26: 0 | BA26: 0 | BC26: 0 | BE26: 0 | BG26: 0 | BI26: 0 | BK26: 0 | BM26: 0 | BO26: 0 | BQ26: 0 | BS26: 0 | BU26: 0 | BW26: 0 | BY26: 0 | CA26: 0 | CC26: 0 | CE26: 0 | CG26: 0 | CI26: 0 | CK26: 0 | CM26: 0 | CO26: 0 | CQ26: 0 | CS26: 0 | CU26: 0 | CW26: 0 | CY26: 0 | DA26: 0 | DC26: 0 | DE26: 0 | DG26: 0 | DI26: 0 | DK26: 0 | DM26: 0 | DO26: 0 | DQ26: 0 | DS26: 0 | DU26: 0 | DW26: 0 | DY26: 0 | EA26: 0 | EC26: 0 | EE26: 0 | EG26: 0 | EI26: 0 | EK26: 0 | EM26: 0 | EO26: 0 | EQ26: 0 | ES26: =+$EY26 -> 0 | EU26: =IF( SUM($EQ26:ES26)<0, "n/a", SUM($EQ26:ES26)/EU$74) -> 0 | EX26: AMW OS | EY26: =IF(ISERROR(VLOOKUP(EX26,IQSH01E!$A$1:$M$400,2,0)),0,VLOOKUP(EX26,IQSH01E!$A$1:$M$400,2,0)) -> 0 | EZ26: 2 spaces
B27: Grand Total | C27: 19115663 | E27: 18190466 | G27: 17762389 | I27: 13671508 | K27: 12956962 | M27: 15580285 | O27: 17997322 | Q27: 16786583 | S27: 19371522 | U27: 19326916 | W27: 15620682 | Y27: 15641393 | AA27: 19361754 | AC27: 15856143 | AE27: 21996902 | AG27: 19516666 | AI27: 16354097 | AK27: 21607646 | AM27: 20156606 | AO27: 19495233 | AQ27: 20466942 | AS27: 18786633 | AU27: 17146493 | AW27: 15993097 | AY27: 18799312 | BA27: 16622267 | BC27: 23058073 | BE27: 20272310 | BG27: 19156903 | BI27: 20800650 | BK27: 16246455 | BM27: 19327892 | BO27: 17803865 | BQ27: 18551188 | BS27: 17169504 | BU27: 15953656 | BW27: 17580660 | BY27: 18368067 | CA27: 21634231 | CC27: 16579102 | CE27: 16053584 | CG27: 18361680 | CI27: 16741482 | CK27: 20049187 | CM27: 19122451 | CO27: 20159998 | CQ27: 17286848 | CS27: 16221144 | CU27: 20071831 | CW27: 19681091 | CY27: 18506512 | DA27: 19510558 | DC27: 18720736 | DE27: 18210639 | DG27: 18529383 | DI27: 19502573 | DK27: 16721729 | DM27: 19175535 | DO27: 16135957 | DQ27: 17783279 | DS27: 19886110 | DU27: 18078454 | DW27: 18051357 | DY27: 17537994 | EA27: 17277057 | EC27: 17396386 | EE27: 19862032 | EG27: 18560285 | EI27: 17304344 | EK27: 18243705 | EM27: 15258549 | EO27: 18306439 | EQ27: 18243233 | ES27: =SUM(ES24:ES26) -> 18180176 | EU27: =IF( SUM($EQ27:ES27)<0, "n/a", SUM($EQ27:ES27)/EU$74) -> 18211705 | EX27: AMW T | EY27: =IF(ISERROR(VLOOKUP(EX27,IQSH01E!$A$1:$M$400,2,0)),0,VLOOKUP(EX27,IQSH01E!$A$1:$M$400,2,0)) -> 18180176 | EZ27: 1 space
B28: Intermodal | C28: 0 | D28: 0 | E28: 0 | F28: 0 | G28: 0 | H28: 0 | I28: 0 | J28: 0 | K28: 0 | L28: 0 | M28: 175769 | N28: 0.10425356 | O28: 178340 | P28: 0.09136233 | Q28: 129477 | R28: 0.06427329 | S28: 42000 | T28: 0.021313024 | U28: 206538 | V28: 0.11160373 | W28: 208060 | X28: 0.11158521 | Y28: 127208 | Z28: 0.073913061 | AA28: 212101 | AB28: 0.10383558 | AC28: 125276 | AD28: 0.065046543 | AE28: 123680 | AF28: 0.059121448 | AG28: 123431 | AH28: 0.06359171 | AI28: 128535 | AJ28: 0.063177188 | AK28: 207557 | AL28: 0.10553003 | AM28: 118056 | AN28: 0.059640659 | AO28: 83137 | AP28: 0.0376957 | AQ28: 208353 | AR28: 0.1193634 | AS28: 168862 | AT28: 0.077240454 | AU28: 163964 | AV28: 0.074079663 | AW28: 123503 | AX28: 0.062563068 | AY28: 204001 | AZ28: 0.095528179 | BA28: 208506 | BB28: 0.14947888 | BC28: 338041 | BD28: 0.16392935 | BE28: 252045 | BF28: 0.12727045 | BG28: 375382 | BH28: 0.15813834 | BI28: 213977 | BJ28: 0.090111552 | BK28: 173761 | BL28: 0.077659172 | BM28: 257294 | BN28: 0.12599419 | BO28: 171458 | BP28: 0.093251506 | BQ28: 215262 | BR28: 0.10252798 | BS28: 173325 | BT28: 0.10240774 | BU28: 85995 | BV28: 0.058520462 | BW28: 210724 | BX28: 0.11425969 | BY28: 0 | BZ28: 0 | CA28: 0 | CB28: 0 | CC28: 0 | CD28: 0 | CE28: 0 | CF28: 0 | CG28: 0 | CH28: 0 | CI28: 0 | CJ28: 0 | CK28: 0 | CL28: 0 | CM28: 0 | CN28: 0 | CO28: 0 | CP28: 0 | CQ28: 0 | CR28: 0 | CS28: 0 | CT28: 0 | CU28: 0 | CV28: 0 | CW28: 0 | CX28: 0 | CY28: 0 | CZ28: 0 | DA28: 0 | DB28: 0 | DC28: 0 | DD28: 0 | DE28: 0 | DF28: 0 | DG28: 0 | DH28: 0 | DI28: 0 | DJ28: 0 | DK28: 0 | DL28: 0 | DM28: 0 | DN28: 0 | DO28: 0 | DP28: 0 | DQ28: 0 | DR28: 0 | DS28: 0 | DT28: 0 | DU28: 0 | DV28: 0 | DW28: 0 | DX28: 0 | DY28: 0 | DZ28: 0 | EA28: 0 | EB28: 0 | EC28: 0 | ED28: 0 | EE28: 0 | EF28: 0 | EG28: 0 | EH28: 0 | EI28: 0 | EJ28: 0 | EK28: 0 | EL28: 0 | EM28: 0 | EN28: 0 | EO28: 0 | EP28: 0 | EQ28: 0 | ER28: 0 | ES28: =+$EY28 -> 0 | ET28: =ES28/ES35 -> 0 | EU28: =IF( SUM($EQ28:ES28)<0, "n/a", SUM($EQ28:ES28)/EU$74) -> 0 | EV28: =EU28/EU35 -> 0 | EX28: AMDI | EY28: =IF(ISERROR(VLOOKUP(EX28,IQSH01E!$A$1:$M$400,2,0)),0,VLOOKUP(EX28,IQSH01E!$A$1:$M$400,2,0)) -> 0 | EZ28: no
B29: FTL | C29: 1799419 | D29: 0.85611729 | E29: 1439418 | F29: 0.81019799 | G29: 1515582 | H29: 0.81437412 | I29: 1431701 | J29: 0.90039218 | K29: 1520288 | L29: 0.88232225 | M29: 1307521 | N29: 0.77552765 | O29: 1458439 | P29: 0.74714806 | Q29: 1508365 | R29: 0.74876295 | S29: 1491711 | T29: 0.75697316 | U29: 1522845 | V29: 0.82287612 | W29: 1393919 | X29: 0.7475764 | Y29: 1390011 | Z29: 0.80765336 | AA29: 1481643 | AB29: 0.72534908 | AC29: 1445910 | AD29: 0.75075392 | AE29: 1744922 | AF29: 0.83410669 | AG29: 1387512 | AH29: 0.71484684 | AI29: 1547546 | AJ29: 0.76064578 | AK29: 1419644 | AL29: 0.72180211 | AM29: 1590067 | AN29: 0.80328525 | AO29: 1797192 | AP29: 0.81487678 | AQ29: 1341586 | AR29: 0.76858155 | AS29: 1653176 | AT29: 0.75619183 | AU29: 1781374 | AV29: 0.80483268 | AW29: 1656410 | AX29: 0.83908967 | AY29: 1653428 | AZ29: 0.77425584 | BA29: 1084618 | BB29: 0.77756749 | BC29: 1522931 | BD29: 0.738529 | BE29: 1450038 | BF29: 0.73219857 | BG29: 1851600 | BH29: 0.7800293 | BI29: 2072994 | BJ29: 0.87299433 | BK29: 1864503 | BL29: 0.83330413 | BM29: 1596014 | BN29: 0.78155143 | BO29: 1497543 | BP29: 0.81447433 | BQ29: 1738701 | BR29: 0.82813268 | BS29: 1428749 | BT29: 0.84416534 | BU29: 1285245 | BV29: 0.87462215 | BW29: 1463561 | BX29: 0.79357844 | BY29: 1113083 | BZ29: 0.92050125 | CA29: 1313477 | CB29: 0.92400384 | CC29: 1178922 | CD29: 0.90077316 | CE29: 1263495 | CF29: 0.9119784 | CG29: 1014215 | CH29: 0.84243843 | CI29: 1208754 | CJ29: 0.90549475 | CK29: 1723306 | CL29: 0.95421574 | CM29: 1323689 | CN29: 0.88920365 | CO29: 1825324 | CP29: 0.91309663 | CQ29: 911720 | CR29: 0.86766682 | CS29: 1495916 | CT29: 0.94841319 | CU29: 1433780 | CV29: 0.97173077 | CW29: 1520920 | CX29: 0.91211838 | CY29: 1297918 | CZ29: 0.98340978 | DA29: 1404460 | DB29: 0.91408228 | DC29: 1387752 | DD29: 0.86777184 | DE29: 1272537 | DF29: 0.95070167 | DG29: 1577328 | DH29: 0.91499243 | DI29: 1657111 | DJ29: 0.93947669 | DK29: 1293021 | DL29: 0.90332548 | DM29: 1324551 | DN29: 0.90732179 | DO29: 1556641 | DP29: 0.94709927 | DQ29: 1431844 | DR29: 0.96012048 | DS29: 1095801 | DT29: 0.91373782 | DU29: 1246002 | DV29: 0.82896144 | DW29: 1403480 | DX29: 0.9127506 | DY29: 1355154 | DZ29: 0.90652362 | EA29: 1196560 | EB29: 0.85398667 | EC29: 1397681 | ED29: 0.90819839 | EE29: 1430111 | EF29: 0.90993026 | EG29: 1001478 | EH29: 0.91564038 | EI29: 1029075 | EJ29: 0.89830748 | EK29: 1349471 | EL29: 0.86337577 | EM29: 885645 | EN29: 0.91294667 | EO29: 994031 | EP29: 0.92067016 | EQ29: 955206 | ER29: 0.91498859 | ES29: =+$EY29 -> 1127132 | ET29: =ES29/ES35 -> 0.91079239 | EU29: =IF( SUM($EQ29:ES29)<0, "n/a", SUM($EQ29:ES29)/EU$74) -> 1041169.5 | EV29: =EU29/EU35 -> 0.91271248 | EX29: All Others | EY29: =+EY38-EY37-EY36-EY28-EY31-EY32-EY33-EY34-EY30 -> 1127132
B30: Railcar | C30: 185200 | D30: 0.088113398 | E30: 184800 | F30: 0.10401745 | G30: 187800 | H30: 0.10091137 | I30: 0 | J30: 0 | K30: 0 | L30: 0 | M30: 0 | N30: 0 | O30: 190950 | P30: 0.097822345 | Q30: 185550 | R30: 0.09210832 | S30: 185800 | T30: 0.09428476 | U30: 0 | V30: 0 | W30: 188750 | X30: 0.10122901 | Y30: 0 | Z30: 0 | AA30: 177650 | AB30: 0.086969846 | AC30: 185200 | AD30: 0.096160636 | AE30: 0 | AF30: 0 | AG30: 190650 | AH30: 0.098222971 | AI30: 193050 | AJ30: 0.094887433 | AK30: 192850 | AL30: 0.098052425 | AM30: 0 | AN30: 0 | AO30: 193450 | AP30: 0.087713452 | AQ30: 0 | AR30: 0 | AS30: 189100 | AT30: 0.086497672 | AU30: 186500 | AV30: 0.084261528 | AW30: 0 | AX30: 0 | AY30: 0 | AZ30: 0 | BA30: 0 | BB30: 0 | BC30: 0 | BD30: 0 | BE30: 0 | BF30: 0 | BG30: 0 | BH30: 0 | BI30: 0 | BJ30: 0 | BK30: 0 | BL30: 0 | BM30: 0 | BN30: 0 | BO30: 0 | BP30: 0 | BQ30: 0 | BR30: 0 | BS30: 0 | BT30: 0 | BU30: 0 | BV30: 0 | BW30: 0 | BX30: 0 | BY30: 0 | BZ30: 0 | CA30: 0 | CB30: 0 | CC30: 0 | CD30: 0 | CE30: 0 | CF30: 0 | CG30: 0 | CH30: 0 | CI30: 0 | CJ30: 0 | CK30: 0 | CL30: 0 | CM30: 0 | CN30: 0 | CO30: 0 | CP30: 0 | CQ30: 0 | CR30: 0 | CS30: 0 | CT30: 0 | CU30: 0 | CV30: 0 | CW30: 0 | CX30: 0 | CY30: 0 | CZ30: 0 | DA30: 0 | DB30: 0 | DC30: 0 | DD30: 0 | DE30: 0 | DF30: 0 | DG30: 0 | DH30: 0 | DI30: 0 | DJ30: 0 | DK30: 0 | DL30: 0 | DM30: 0 | DN30: 0 | DO30: 0 | DP30: 0 | DQ30: 0 | DR30: 0 | DS30: 0 | DT30: 0 | DU30: 0 | DV30: 0 | DW30: 0 | DX30: 0 | DY30: 0 | DZ30: 0 | EA30: 0 | EB30: 0 | EC30: 0 | ED30: 0 | EE30: 0 | EF30: 0 | EG30: 0 | EH30: 0 | EI30: 0 | EJ30: 0 | EK30: 0 | EL30: 0 | EM30: 0 | EN30: 0 | EO30: 0 | EP30: 0 | EQ30: 0 | ER30: 0 | ES30: =+$EY30 -> 0 | ET30: =ES30/ES35 -> 0 | EU30: =IF( SUM($EQ30:ES30)<0, "n/a", SUM($EQ30:ES30)/EU$74) -> 0 | EV30: =EU30/EU35 -> 0 | EX30: AMD RC | EY30: =IF(ISERROR(VLOOKUP(EX30,IQSH01E!$A$1:$M$400,2,0)),0,VLOOKUP(EX30,IQSH01E!$A$1:$M$400,2,0)) -> 0 | EZ30: 2 spaces
B31: LTL | C31: 116345 | D31: 0.055353959 | E31: 108565 | F31: 0.061107437 | G31: 79463 | H31: 0.042698192 | I31: 118917 | J31: 0.074786521 | K31: 81378 | L31: 0.047228959 | M31: 160944 | N31: 0.095460434 | O31: 124059 | P31: 0.063554555 | Q31: 110869 | R31: 0.055036148 | S31: 171188 | T31: 0.086869858 | U31: 121254 | V31: 0.065520143 | W31: 73855 | X31: 0.039609371 | Y31: 121397 | Z31: 0.070536632 | AA31: 171218 | AB31: 0.083821014 | AC31: 126858 | AD31: 0.065867959 | AE31: 179728 | AF31: 0.085913483 | AG31: 197075 | AH31: 0.10153313 | AI31: 124962 | AJ31: 0.061420996 | AK31: 105999 | AL31: 0.053894006 | AM31: 231342 | AN31: 0.11687156 | AO31: 131653 | AP31: 0.059693663 | AQ31: 93905 | AR31: 0.05379726 | AS31: 93925 | AT31: 0.04296295 | AU31: 41509 | AV31: 0.01875395 | AW31: 194123 | AX31: 0.098337129 | AY31: 156369 | AZ31: 0.073223395 | BA31: 101762 | BB31: 0.072953632 | BC31: 120712 | BD31: 0.058537986 | BE31: 157656 | BF31: 0.079608602 | BG31: 146037 | BH31: 0.061521462 | BI31: 87508 | BJ31: 0.036852006 | BK31: 160318 | BL31: 0.071651079 | BM31: 146929 | BN31: 0.071949601 | BO31: 89816 | BP31: 0.048848565 | BQ31: 102971 | BR31: 0.049044459 | BS31: 90385 | BT31: 0.053403281 | BU31: 98196 | BV31: 0.066823365 | BW31: 130170 | BX31: 0.070581346 | BY31: 96031 | BZ31: 0.07941605 | CA31: 105639 | CB31: 0.074314846 | CC31: 87447 | CD31: 0.066815201 | CE31: 81443 | CF31: 0.058784765 | CG31: 106537 | CH31: 0.088492936 | CI31: 88536 | CJ31: 0.066323572 | CK31: 81166 | CL31: 0.044942613 | CM31: 126124 | CN31: 0.08472528 | CO31: 86942 | CP31: 0.043491702 | CQ31: 98204 | CR31: 0.093458905 | CS31: 81367 | CT31: 0.051586811 | CU31: 40811 | CV31: 0.027659267 | CW31: 103858 | CX31: 0.06228519 | CY31: 21696 | CZ31: 0.01643868 | DA31: 132010 | DB31: 0.08591772 | DC31: 128051 | DD31: 0.08007126 | DE31: 65987 | DF31: 0.049298332 | DG31: 104036 | DH31: 0.060350258 | DI31: 64826 | DJ31: 0.036752225 | DK31: 99540 | DL31: 0.069540262 | DM31: 94623 | DN31: 0.064817066 | DO31: 49409 | DP31: 0.03006167 | DQ31: 57823 | DR31: 0.038773111 | DS31: 59322 | DT31: 0.049465875 | DU31: 94225 | DV31: 0.062687614 | DW31: 132878 | DX31: 0.086416959 | DY31: 99135 | DZ31: 0.066315872 | EA31: 124770 | EB31: 0.089048536 | EC31: 99029 | ED31: 0.064348001 | EE31: 98450 | EF31: 0.062640336 | EG31: 91943 | EH31: 0.084062479 | EI31: 75444 | EJ31: 0.065857114 | EK31: 47724 | EL31: 0.030533257 | EM31: 42855 | EN31: 0.044176086 | EO31: 85616 | EP31: 0.079297423 | EQ31: 84432 | ER31: 0.080877127 | ES31: =+$EY31 -> 67897 | ET31: =ES31/ES35 -> 0.054864977 | EU31: =IF( SUM($EQ31:ES31)<0, "n/a", SUM($EQ31:ES31)/EU$74) -> 76164.54 | EV31: =EU31/EU35 -> 0.066767543 | EX31: AMD L | EY31: =IF(ISERROR(VLOOKUP(EX31,IQSH01E!$A$1:$M$400,2,0)),0,VLOOKUP(EX31,IQSH01E!$A$1:$M$400,2,0)) -> 67897 | EZ31: 1 space
